2019-09-24 15:42:29 ERROR (SyncWorker_11) [concurrent.futures] exception calling callback for <Future at 0x7f9549d07b00 state=finished returned NoneType>
Traceback (most recent call last):
  File "/home/jack/anaconda3/envs/homeassistant/lib/python3.6/concurrent/futures/_base.py", line 324, in _invoke_callbacks
    callback(self)
  File "/home/jack/anaconda3/envs/homeassistant/lib/python3.6/asyncio/futures.py", line 417, in _call_set_state
    dest_loop.call_soon_threadsafe(_set_state, destination, source)
  File "/home/jack/anaconda3/envs/homeassistant/lib/python3.6/asyncio/base_events.py", line 637, in call_soon_threadsafe
    self._check_closed()
  File "/home/jack/anaconda3/envs/homeassistant/lib/python3.6/asyncio/base_events.py", line 377, in _check_closed
    raise RuntimeError('Event loop is closed')
RuntimeError: Event loop is closed
